Workbook
Name Scenario: Drivers!$C$4

Sheet Summary
A1: FTAI Aviation (NASDAQ: FTAI): valuation summary
A2: [TEAM NAME] | Point72 Academy pitch | market data as of 10/6/26 | USD m except per-share | Scenario selected on Drivers tab
A4: RECOMMENDATION (formula-driven) | B4: =IF(Valuation!B100>Drivers!$D$228,"LONG",IF(Valuation!B100<-Drivers!$D$228,"SHORT","NEUTRAL / marginal"))&": probability-weighted value $"&TEXT(Valuation!B98,"0")&" vs price $"&TEXT(Drivers!$D$180,"0.00")&" ("&TEXT(Valuation!B100,"0%")&")"&IF(ABS(ABS(Valuation!B100)-Drivers!$D$228)<Drivers!$D$229," - MARGINAL call","")
A5: Current price ($) | B5: =Drivers!$D$180
A6: Probability-weighted blended price target ($) | B6: =Valuation!B98
A7: Upside / (downside) vs current price | B7: =Valuation!B100
A8: Base-case blended price target ($) and upside | B8: =Valuation!C93 | C8: =B8/Drivers!$D$180-1
A9: Street mean PT ($, methodology not public) | B9: =Drivers!$D$215
A11: Price target by method: selected scenario (live)
A12: Scenario currently selected | B12: =Drivers!$C$4
A13: Method | B13: Value / share | C13: Weight | D13: vs price
A14: SOTP (2027E, Leasing at book) | B14: =Valuation!B68 | C14: =Valuation!C68 | D14: =B14/Drivers!$D$180-1
A15: Forward P/E x FY27E EPS | B15: =Valuation!B69 | C15: =Valuation!C69 | D15: =B15/Drivers!$D$180-1
A16: DCF (clean FCF) | B16: =Valuation!B70 | C16: =Valuation!C70 | D16: =B16/Drivers!$D$180-1
A17: Blended (weights are inputs on Drivers) | B17: =Valuation!D71 | C17: =Valuation!C71 | D17: =B17/Drivers!$D$180-1
A18: Model FY27E EPS ($) vs consensus-implied ($8.87) | B18: =Valuation!B39 | C18: =Valuation!B43 | D18: =Valuation!B46
A20: Scenario table (SOTP is live; EPS, P/E, DCF, blended come from the snapshot of four full recalculations)
A21: Metric | B21: Bear | C21: Base | D21: Bull | E21: Mgmt Guide | F21: Prob-weighted
A22: Probability weight | B22: =Valuation!B97 | C22: =Valuation!C97 | D22: =Valuation!D97 | E22: =Valuation!E97 | F22: =SUM(B22:E22)
A23: FY26E segment EBITDA ($M) | B23: =Valuation!B85 | C23: =Valuation!C85 | D23: =Valuation!D85 | E23: =Valuation!E85 | F23: =SUMPRODUCT(B23:E23,$B$22:$E$22)/SUM($B$22:$E$22)
A24: FY27E segment EBITDA ($M) | B24: =Valuation!B86 | C24: =Valuation!C86 | D24: =Valuation!D86 | E24: =Valuation!E86 | F24: =SUMPRODUCT(B24:E24,$B$22:$E$22)/SUM($B$22:$E$22)
A25: FY27E diluted EPS ($) | B25: =Valuation!B89 | C25: =Valuation!C89 | D25: =Valuation!D89 | E25: =Valuation!E89 | F25: =SUMPRODUCT(B25:E25,$B$22:$E$22)/SUM($B$22:$E$22)
A26: SOTP value / share ($) | B26: =Valuation!B31 | C26: =Valuation!C31 | D26: =Valuation!D31 | E26: =Valuation!E31 | F26: =SUMPRODUCT(B26:E26,$B$22:$E$22)/SUM($B$22:$E$22)
A27: P/E value / share ($) | B27: =Valuation!B91 | C27: =Valuation!C91 | D27: =Valuation!D91 | E27: =Valuation!E91 | F27: =SUMPRODUCT(B27:E27,$B$22:$E$22)/SUM($B$22:$E$22)
A28: DCF value / share ($) | B28: =Valuation!B92 | C28: =Valuation!C92 | D28: =Valuation!D92 | E28: =Valuation!E92 | F28: =SUMPRODUCT(B28:E28,$B$22:$E$22)/SUM($B$22:$E$22)
A29: Blended value / share ($) | B29: =Valuation!B93 | C29: =Valuation!C93 | D29: =Valuation!D93 | E29: =Valuation!E93 | F29: =SUMPRODUCT(B29:E29,$B$22:$E$22)/SUM($B$22:$E$22)
A30: Upside / (downside) vs price (blended) | B30: =B29/Drivers!$D$180-1 | C30: =C29/Drivers!$D$180-1 | D30: =D29/Drivers!$D$180-1 | E30: =E29/Drivers!$D$180-1 | F30: =F29/Drivers!$D$180-1
A32: The 3 KEY ASSUMPTIONS (flagged; values by scenario)
A33: Key assumption | B33: Bear | C33: Base | D33: Bull | E33: Mgmt Guide | F33: Selected
A34: KEY #1: 2027E Aerospace EBITDA ($M) = modules x EBITDA/module (guide is a volume call) | B34: =Drivers!D9 | C34: =Drivers!E9 | D34: =Drivers!F9 | E34: =Drivers!G9 | F34: =Drivers!H9
A35: KEY #2: inventory conversion % (2H26 FCF ramp; Mgmt value back-solved to the $878M guide) | B35: =Drivers!D10 | C35: =Drivers!E10 | D35: =Drivers!F10 | E35: =Drivers!G10 | F35: =Drivers!H10
A36: KEY #3: 2027E Power EBITDA ($M) = units x $7.5M/unit (unverified) | B36: =Drivers!D11 | C36: =Drivers!E11 | D36: =Drivers!F11 | E36: =Drivers!G11 | F36: =Drivers!H11
A38: Thesis in three bullets
A39: 1. Cash quality: FY25 Adjusted FCF of $724M vs CFO+CFI of $412.6M; 1H26 clean cash was about $26M after $176M of non-recurring seed sales and $48M of insurance, and the $878M FY26 guide needs ~$623M in 2H26 (about 3x the Q2 run-rate).
A40: 2. Growth runs through affiliates: 25% of 1H26 Aerospace revenue was sold to the 19%-owned SCI vehicle, Power sits in a JV that Jereh consolidates, and pro-rata SCI/JV EBITDA is counted in Adj. EBITDA but arrives as cash only via distributions.
A41: 3. Valuation: the 2027 guide is roughly our Bull case. On Base (1,920 EBITDA) SOTP and P/E sit near the current price, far below the Street's ~$330; the call depends on the 2027 EBITDA delivery and the Q3 (10/28) FCF test.

Sheet Drivers
A1: Drivers: every projection traces to this tab
A2: Blue = typed input; black = formula; green = link. Yellow fill + red bold label = KEY ASSUMPTION. Scenario selector below drives all 'Selected' rows. USD m unless stated.
A4: SCENARIO SELECTOR (dropdown) | C4: Base | E4: =MATCH(C4,G4:J4,0) | F4: list: | G4: Bear | H4: Base | I4: Bull | J4: Mgmt Guide
A5: Scenario index (formula)
A7: KEY ASSUMPTIONS (3): values by scenario
A8: Key assumption | B8: Unit | D8: Bear | E8: Base | F8: Bull | G8: Mgmt Guide | H8: Selected
A9: KEY #1: 2027 Aerospace EBITDA (modules x EBITDA per module) | B9: $M | D9: =Drivers!$D$263 | E9: =Drivers!$E$263 | F9: =Drivers!$F$263 | G9: =Drivers!$G$263 | H9: =INDEX(D9:G9,$E$4)
A10: KEY #2: Inventory conversion % (drives the 2H26 FCF ramp) | B10: % | D10: =$D$162 | E10: =$D$163 | F10: =$D$164 | G10: =$D$165 | H10: =INDEX(D10:G10,$E$4)
A11: KEY #3: 2027 Power EBITDA (units x EBITDA per unit) | B11: $M | D11: =Drivers!$D$264 | E11: =Drivers!$E$264 | F11: =Drivers!$F$264 | G11: =Drivers!$G$264 | H11: =INDEX(D11:G11,$E$4)
A12: Memo: 2027 segment EBITDA total | D12: =Drivers!$D$266 | E12: =Drivers!$E$266 | F12: =Drivers!$F$266 | G12: =Drivers!$G$266 | H12: =INDEX(D12:G12,$E$4)
A16: 0. General constants
A17: Driver | B17: Unit | C17: Q2'26A | D17: Q3'26E | E17: Q4'26E | F17: Q1'27E | G17: Q2'27E | H17: Q3'27E | I17: Q4'27E | J17: FY2028E | K17: FY2029E | L17: FY2030E | M17: Source / rationale
A18: Quarters per year | B18: # | D18: 4 | M18: Calendar constant
A19: Days per quarter | B19: days | D19: 91.25 | M19: 365/4
A20: Days per year | B20: days | D20: 365 | M20: Calendar constant
A21: Months per year | B21: months | D21: 12 | M21: Calendar constant
A22: Quarters of actuals in 1H26 | B22: # | D22: 2 | M22: Q1-26 and Q2-26 actuals
A23: Preferred liquidation preference per share | B23: $ | D23: 25 | M23: $25 per preferred share (balance_sheet.csv label)
A24: 1. Aerospace (SCI / MRE modules + products)
A25: Driver | B25: Unit | C25: Q2'26A | D25: Q3'26E | E25: Q4'26E | F25: Q1'27E | G25: Q2'27E | H25: Q3'27E | I25: Q4'27E | J25: FY2028E | K25: FY2029E | L25: FY2030E | M25: Source / rationale
A26: Modules produced and sold per quarter | B26: units | M26: KEY #1. 2027 totals Bear 1,350 / Base 1,500 / Bull 1,700 / Mgmt 1,700 per A_2027_guide_segment_build.csv. 2026 Mgmt total 1,200 (Q2-26 call). 2H26 splits are analyst assumptions (Q2-26 actual 296)
A27: Bear | D27: 285 | E27: 295 | F27: 315 | G27: 330 | H27: 350 | I27: 355
A28: Base | D28: 305 | E28: 320 | F28: 355 | G28: 370 | H28: 385 | I28: 390
A29: Bull | D29: 315 | E29: 345 | F29: 400 | G29: 420 | H29: 435 | I29: 445
A30: Mgmt Guide | D30: 310 | E30: 330 | F30: 400 | G30: 420 | H30: 435 | I30: 445
A31: Selected scenario (live) | D31: =INDEX(D27:D30,$E$4) | E31: =INDEX(E27:E30,$E$4) | F31: =INDEX(F27:F30,$E$4) | G31: =INDEX(G27:G30,$E$4) | H31: =INDEX(H27:H30,$E$4) | I31: =INDEX(I27:I30,$E$4)
A33: Module growth y/y (FY28-FY30) | B33: % | M33: ASSUMPTION: guidance ends 2027. Mgmt Guide FY28+ set equal to Bull. Rationale: 3,000-module physical capacity, GE shop-visit demand ~2,400/yr
A34: Bear | J34: 0.03 | K34: 0.03 | L34: 0.03
A35: Base | J35: 0.08 | K35: 0.06 | L35: 0.05
A36: Bull | J36: 0.12 | K36: 0.1 | L36: 0.08
A37: Mgmt Guide | J37: 0.12 | K37: 0.1 | L37: 0.08
A38: Selected scenario (live) | J38: =INDEX(J34:J37,$E$4) | K38: =INDEX(K34:K37,$E$4) | L38: =INDEX(L34:L37,$E$4)
A40: Aerospace revenue per module (products + MRE) | B40: $M | D40: 2.96 | E40: 2.96 | F40: 2.96 | G40: 2.96 | H40: 2.96 | I40: 2.96 | M40: Q2-26 actual: 875.0 segment revenue / 296 modules = 2.956 (A_2027_guide.md uses ~2.96)
A42: Revenue per module growth y/y (FY28-FY30) | B42: % | J42: 0 | K42: 0 | L42: 0 | M42: ASSUMPTION: flat pricing/mix
A44: Aerospace EBITDA per module | B44: $M | M44: 2027: Bear 0.78 / Base 0.82 / Bull 0.84 per A segment build (rounded to land 1,050 / 1,230 / 1,430); Mgmt 0.8235 = 1,400/1,700. Mgmt 2H26 0.9027 solves to 1,050 FY26 guide. Q2-26 actual 0.84
A45: Bear | D45: 0.8 | E45: 0.8 | F45: 0.7778 | G45: 0.7778 | H45: 0.7778 | I45: 0.7778
A46: Base | D46: 0.84 | E46: 0.84 | F46: 0.82 | G46: 0.82 | H46: 0.82 | I46: 0.82
A47: Bull | D47: 0.86 | E47: 0.88 | F47: 0.8412 | G47: 0.8412 | H47: 0.8412 | I47: 0.8412
A48: Mgmt Guide | D48: 0.9027 | E48: 0.9027 | F48: 0.8235 | G48: 0.8235 | H48: 0.8235 | I48: 0.8235
A49: Selected scenario (live) | D49: =INDEX(D45:D48,$E$4) | E49: =INDEX(E45:E48,$E$4) | F49: =INDEX(F45:F48,$E$4) | G49: =INDEX(G45:G48,$E$4) | H49: =INDEX(H45:H48,$E$4) | I49: =INDEX(I45:I48,$E$4)
...

Sheet Historical
A1: Historical financials (typed inputs, blue; each row cites its source)
A2: USD millions except per-share. Fiscal year = calendar year. Q4 figures are derived as FY less 9M, so 'quarters sum to FY' for IS rows holds by construction (not independent verification).
A4: USD m | B4: FY2023A | C4: FY2024A | D4: FY2025A | E4: Q1'24A | F4: Q2'24A | G4: Q3'24A | H4: Q4'24A | I4: Q1'25A | J4: Q2'25A | K4: Q3'25A | L4: Q4'25A | M4: Q1'26A | N4: Q2'26A | O4: Source / rationale
A5: Income statement (USD m, EPS in $)
A6: Aerospace products revenue (ex-MRE) | B6: 454.97 | C6: 1079.821 | D6: 1600.456 | E6: 189.057 | F6: 245.2 | G6: 303.469 | H6: 342.095 | I6: 264.425 | J6: 420.686 | K6: 459.206 | L6: 456.139 | M6: 522.585 | N6: 692.229 | O6: SEC EDGAR 10-Q/10-K segment note, latest filing containing each period (Q2-26 10-Q acc 0001628280-26-051412; FY25 10-K; Q4 = FY less 9M, derived). Via phase2/data/is_quarterly.csv
A7: MRE Contract revenue (to 2025 Partnership) | D7: 335.788 | I7: 100.638 | J7: 69.585 | K7: 58.663 | L7: 106.902 | M7: 221.23 | N7: 182.799 | O7: SEC EDGAR 10-Q/10-K segment note, latest filing containing each period (Q2-26 10-Q acc 0001628280-26-051412; FY25 10-K; Q4 = FY less 9M, derived). Via phase2/data/is_quarterly.csv. Starts Q1-25
A8: Lease income | B8: 207.936 | C8: 255.338 | D8: 235.21 | E8: 53.24 | F8: 70.754 | G8: 65.45 | H8: 65.973 | I8: 68.44 | J8: 62.439 | K8: 55.072 | L8: 49.259 | M8: 39.892 | N8: 27.765 | O8: SEC EDGAR 10-Q/10-K segment note, latest filing containing each period (Q2-26 10-Q acc 0001628280-26-051412; FY25 10-K; Q4 = FY less 9M, derived). Via phase2/data/is_quarterly.csv. FY24 differs from quarterly sum by 0.08 (recast between lease income and other revenue; total unaffected)
A9: Maintenance revenue | B9: 191.347 | C9: 200.809 | D9: 218.499 | E9: 45.79 | F9: 51.187 | G9: 59.917 | H9: 43.915 | I9: 49.607 | J9: 73.104 | K9: 52.37 | L9: 43.418 | M9: 30.599 | N9: 25.793 | O9: SEC EDGAR 10-Q/10-K segment note, latest filing containing each period (Q2-26 10-Q acc 0001628280-26-051412; FY25 10-K; Q4 = FY less 9M, derived). Via phase2/data/is_quarterly.csv
A10: Asset sales revenue | B10: 303.141 | C10: 192.176 | D10: 106.945 | E10: 38.607 | F10: 72.433 | G10: 34.953 | H10: 46.183 | I10: 18.939 | J10: 47.915 | K10: 38.461 | L10: 1.63 | M10: 10.184 | N10: 16.925 | O10: SEC EDGAR 10-Q/10-K segment note, latest filing containing each period (Q2-26 10-Q acc 0001628280-26-051412; FY25 10-K; Q4 = FY less 9M, derived). Via phase2/data/is_quarterly.csv
A11: Other revenue | B11: 13.502 | C11: 6.757 | D11: 10.511 | F11: 4.02 | G11: 2.005 | H11: 0.653 | I11: 0.031 | J11: 2.508 | K11: 3.292 | L11: 4.68 | M11: 6.207 | N11: 7.574 | O11: SEC EDGAR 10-Q/10-K segment note, latest filing containing each period (Q2-26 10-Q acc 0001628280-26-051412; FY25 10-K; Q4 = FY less 9M, derived). Via phase2/data/is_quarterly.csv
A12: Total revenues (reported) | B12: 1170.896 | C12: 1734.901 | D12: 2507.409 | E12: 326.694 | F12: 443.594 | G12: 465.794 | H12: 498.819 | I12: 502.08 | J12: 676.237 | K12: 667.064 | L12: 662.028 | M12: 830.697 | N12: 953.085 | O12: SEC EDGAR 10-Q/10-K segment note, latest filing containing each period (Q2-26 10-Q acc 0001628280-26-051412; FY25 10-K; Q4 = FY less 9M, derived). Via phase2/data/is_quarterly.csv
A13: check: components less total (should be ~0) | B13: =SUM(B6:B11)-B12 | C13: =SUM(C6:C11)-C12 | D13: =SUM(D6:D11)-D12 | E13: =SUM(E6:E11)-E12 | F13: =SUM(F6:F11)-F12 | G13: =SUM(G6:G11)-G12 | H13: =SUM(H6:H11)-H12 | I13: =SUM(I6:I11)-I12 | ... N13: =SUM(N6:N11)-N12 | O13: Formula check (small FY24 differences are source recasts)
A14: Aerospace segment revenue (products + MRE) | B14: 454.97 | C14: 1079.821 | D14: 1936.244 | E14: 189.057 | F14: 245.2 | G14: 303.469 | H14: 342.095 | I14: 365.063 | J14: 490.271 | K14: 517.869 | L14: 563.041 | M14: 743.815 | N14: 875.028 | O14: SEC EDGAR 10-Q/10-K segment note, latest filing containing each period (Q2-26 10-Q acc 0001628280-26-051412; FY25 10-K; Q4 = FY less 9M, derived). Via phase2/data/is_quarterly.csv
A15: Aviation Leasing segment revenue | B15: 681.611 | C15: 628.437 | D15: 571.161 | E15: 135.31 | F15: 184.437 | G15: 152.266 | H15: 156.424 | I15: 137.013 | J15: 185.966 | K15: 149.195 | L15: 98.987 | M15: 86.882 | N15: 78.057 | O15: SEC EDGAR 10-Q/10-K segment note, latest filing containing each period (Q2-26 10-Q acc 0001628280-26-051412; FY25 10-K; Q4 = FY less 9M, derived). Via phase2/data/is_quarterly.csv
A16: Cost of sales (total) | B16: 502.132 | C16: 825.884 | D16: 1349.719 | E16: 142.804 | F16: 205.857 | G16: 219.496 | H16: 257.727 | I16: 248.714 | J16: 369.258 | K16: 362.922 | L16: 368.825 | M16: 524.268 | N16: 635.782 | O16: SEC EDGAR 10-Q/10-K segment note, latest filing containing each period (Q2-26 10-Q acc 0001628280-26-051412; FY25 10-K; Q4 = FY less 9M, derived). Via phase2/data/is_quarterly.csv
A17: Cost of sales - Aerospace segment | B17: 280.28 | C17: 673.907 | D17: 1240.368 | E17: 110.915 | F17: 146.888 | G17: 198.812 | H17: 217.292 | I17: 228.755 | J17: 317.469 | K17: 328.153 | L17: 365.991 | M17: 511.012 | N17: 614.529 | O17: SEC EDGAR 10-Q/10-K segment note, latest filing containing each period (Q2-26 10-Q acc 0001628280-26-051412; FY25 10-K; Q4 = FY less 9M, derived). Via phase2/data/is_quarterly.csv
A18: Operating expenses | B18: 110.163 | C18: 115.861 | D18: 152.541 | E18: 25.317 | F18: 29.099 | G18: 26.858 | H18: 34.587 | I18: 32.438 | J18: 34.328 | K18: 39.092 | L18: 46.683 | M18: 64.987 | N18: 67.567 | O18: SEC EDGAR 10-Q/10-K segment note, latest filing containing each period (Q2-26 10-Q acc 0001628280-26-051412; FY25 10-K; Q4 = FY less 9M, derived). Via phase2/data/is_quarterly.csv
A19: General and administrative | B19: 13.7 | C19: 14.263 | D19: 9.478 | E19: 3.683 | F19: 2.969 | G19: 4.045 | H19: 3.566 | I19: 3.116 | J19: 2.442 | K19: 1.829 | L19: 2.091 | M19: 2.413 | N19: 2.245 | O19: SEC EDGAR 10-Q/10-K segment note, latest filing containing each period (Q2-26 10-Q acc 0001628280-26-051412; FY25 10-K; Q4 = FY less 9M, derived). Via phase2/data/is_quarterly.csv
A20: Acquisition and transaction expenses | B20: 15.194 | C20: 32.296 | D20: 28.587 | E20: 6.179 | F20: 8.019 | G20: 9.341 | H20: 8.757 | I20: 7.292 | J20: 4.489 | K20: 7.066 | L20: 9.74 | M20: 16.361 | N20: 5.699 | O20: SEC EDGAR 10-Q/10-K segment note, latest filing containing each period (Q2-26 10-Q acc 0001628280-26-051412; FY25 10-K; Q4 = FY less 9M, derived). Via phase2/data/is_quarterly.csv
A21: Depreciation and amortization | B21: 169.877 | C21: 218.064 | D21: 225.797 | E21: 49.92 | F21: 56.691 | G21: 56.775 | H21: 54.678 | I21: 59.562 | J21: 55.236 | K21: 55.278 | L21: 55.721 | M21: 52.289 | N21: 46.986 | O21: SEC EDGAR 10-Q/10-K segment note, latest filing containing each period (Q2-26 10-Q acc 0001628280-26-051412; FY25 10-K; Q4 = FY less 9M, derived). Via phase2/data/is_quarterly.csv
A22: Interest expense (positive = expense) | B22: 161.639 | C22: 221.721 | D22: 247.751 | E22: 47.707 | F22: 55.196 | G22: 57.937 | H22: 60.881 | I22: 62.04 | J22: 63.965 | K22: 60.784 | L22: 60.962 | M22: 61.407 | N22: 64.102 | O22: SEC EDGAR 10-Q/10-K segment note, latest filing containing each period (Q2-26 10-Q acc 0001628280-26-051412; FY25 10-K; Q4 = FY less 9M, derived). Via phase2/data/is_quarterly.csv. Sign normalised to positive in source CSV
A23: Gain on sale to the 2025 Partnership | D23: 46.38 | I23: 10.87 | J23: 34.604 | K23: 4.609 | L23: -3.703 | M23: 15.168 | N23: 2.465 | O23: SEC EDGAR 10-Q/10-K segment note, latest filing containing each period (Q2-26 10-Q acc 0001628280-26-051412; FY25 10-K; Q4 = FY less 9M, derived). Via phase2/data/is_quarterly.csv. Booked in Aviation Leasing
A24: Equity in earnings (losses) of unconsolidated entities | B24: -3.275 | C24: -2.2 | D24: -23.659 | E24: -0.667 | F24: -0.694 | G24: -0.438 | H24: -0.401 | I24: -7.614 | J24: -5.003 | K24: -4.224 | L24: -6.818 | M24: -2.363 | N24: 9.97 | O24: SEC EDGAR 10-Q/10-K segment note, latest filing containing each period (Q2-26 10-Q acc 0001628280-26-051412; FY25 10-K; Q4 = FY less 9M, derived). Via phase2/data/is_quarterly.csv. FY = sum of quarters (the CSV FY25 value of -6.8 is the Q4 figure only). FY23 not complete
A25: Income (loss) before income taxes | D25: 606.684 | E25: 45.194 | F25: -232.903 | G25: 93.813 | I25: 125.245 | J25: 203.276 | K25: 144.048 | L25: 134.115 | M25: 169.359 | N25: 150.713 | O25: SEC EDGAR 10-Q/10-K segment note, latest filing containing each period (Q2-26 10-Q acc 0001628280-26-051412; FY25 10-K; Q4 = FY less 9M, derived). Via phase2/data/is_quarterly.csv. FY23/FY24 and Q4-24 not cleanly parsed in source (continuing/discontinued label variants), left blank
A26: Provision for income taxes | D26: 105.62 | F26: -13.033 | G26: 7.331 | I26: 22.859 | J26: 37.878 | K26: 26.33 | L26: 18.553 | M26: 31.46 | N26: 25.619 | O26: SEC EDGAR 10-Q/10-K segment note, latest filing containing each period (Q2-26 10-Q acc 0001628280-26-051412; FY25 10-K; Q4 = FY less 9M, derived). Via phase2/data/is_quarterly.csv. As above
A27: Net income (loss) | D27: 501.064 | E27: 39.622 | F27: -219.87 | G27: 86.482 | I27: 102.386 | J27: 165.398 | K27: 117.718 | L27: 115.562 | M27: 137.899 | N27: 125.094 | O27: SEC EDGAR 10-Q/10-K segment note, latest filing containing each period (Q2-26 10-Q acc 0001628280-26-051412; FY25 10-K; Q4 = FY less 9M, derived). Via phase2/data/is_quarterly.csv. As above
A28: Net income attributable to shareholders | B28: 212.022 | C28: -32.079 | D28: 477.494 | E28: 31.287 | F28: -228.205 | G28: 78.147 | H28: 86.692 | I28: 89.944 | J28: 161.689 | K28: 114.009 | L28: 111.852 | M28: 134.19 | N28: 117.585 | O28: SEC EDGAR 10-Q/10-K segment note, latest filing containing each period (Q2-26 10-Q acc 0001628280-26-051412; FY25 10-K; Q4 = FY less 9M, derived). Via phase2/data/is_quarterly.csv
A29: Preferred dividends + non-controlling interest (NI less attributable) | B29: =IF(OR(B27="",B28=""),"",B27-B28) | C29: =IF(OR(C27="",C28=""),"",C27-C28) | D29: =IF(OR(D27="",D28=""),"",D27-D28) | E29: =IF(OR(E27="",E28=""),"",E27-E28) | F29: =IF(OR(F27="",F28=""),"",F27-F28) | G29: =IF(OR(G27="",G28=""),"",G27-G28) | H29: =IF(OR(H27="",H28=""),"",H27-H28) | I29: =IF(OR(I27="",I28=""),"",I27-I28) | ... N29: =IF(OR(N27="",N28=""),"",N27-N28) | O29: Formula
A30: Diluted EPS ($) | B30: 2.11 | C30: -0.32 | D30: 4.6 | E30: 0.31 | F30: -2.26 | G30: 0.76 | H30: 0.84 | I30: 0.87 | J30: 1.57 | K30: 1.1 | L30: 1.08 | M30: 1.29 | N30: 1.13 | O30: SEC EDGAR 10-Q/10-K segment note, latest filing containing each period (Q2-26 10-Q acc 0001628280-26-051412; FY25 10-K; Q4 = FY less 9M, derived). Via phase2/data/is_quarterly.csv
A31: Diluted weighted shares (M) | B31: 100.42578 | C31: 101.53884 | D31: 103.84691 | E31: 100.96007 | F31: 100.95852 | G31: 103.39535 | H31: 103.60335 | I31: 103.15905 | J31: 103.14786 | K31: 103.96665 | L31: 103.86494 | M31: 104.2559 | N31: 104.04411 | O31: SEC EDGAR 10-Q/10-K segment note, latest filing containing each period (Q2-26 10-Q acc 0001628280-26-051412; FY25 10-K; Q4 = FY less 9M, derived). Via phase2/data/is_quarterly.csv
A32: Segment Adjusted EBITDA (USD m)
A33: Aerospace Products | B33: 160.009 | C33: 380.636 | D33: 671.252 | E33: 70.277 | F33: 91.24 | G33: 101.814 | H33: 117.305 | I33: 130.945 | J33: 164.864 | K33: 180.421 | L33: 195.022 | M33: 222.576 | N33: 249.716 | O33: Q2-26 8-K Ex99.1 2026-07-29 acc 0001628280-26-050622 and 10-Q MD&A/segment notes (phase2/data/segment_ebitda.csv). Eliminations = Total less 3 segments
A34: Aviation Leasing | B34: 467.388 | C34: 500.062 | D34: 608.912 | E34: 104.807 | F34: 124.981 | G34: 136.423 | H34: 133.851 | I34: 161.989 | J34: 199.303 | K34: 134.408 | L34: 113.212 | M34: 152.959 | N34: 88.21 | O34: Q2-26 8-K Ex99.1 2026-07-29 acc 0001628280-26-050622 and 10-Q MD&A/segment notes (phase2/data/segment_ebitda.csv). Eliminations = Total less 3 segments
A35: Corporate and Other | B35: -30.115 | C35: -18.648 | D35: -66.413 | E35: -10.983 | F35: -2.317 | G35: -6.207 | H35: 0.859 | I35: -17.426 | J35: -11.427 | K35: -13.54 | L35: -24.02 | M35: -39.958 | N35: -39.885 | O35: Q2-26 8-K Ex99.1 2026-07-29 acc 0001628280-26-050622 and 10-Q MD&A/segment notes (phase2/data/segment_ebitda.csv). Eliminations = Total less 3 segments
A36: Eliminations (profit elimination on sales to 2025 Partnership) | B36: 0 | C36: 0 | D36: -22.829 | E36: 0 | F36: 0 | G36: 0 | H36: 0 | I36: -6.95 | J36: -4.935 | K36: -3.908 | L36: -7.036 | M36: -10 | N36: -6.597 | O36: Q2-26 8-K Ex99.1 2026-07-29 acc 0001628280-26-050622 and 10-Q MD&A/segment notes (phase2/data/segment_ebitda.csv). Eliminations = Total less 3 segments
A37: Total Adjusted EBITDA (company basis) | B37: 597.282 | C37: 862.05 | D37: 1190.922 | E37: 164.101 | F37: 213.904 | G37: 232.03 | H37: 252.015 | I37: 268.558 | J37: 347.805 | K37: 297.381 | L37: 277.178 | M37: 325.577 | N37: 291.444 | O37: Q2-26 8-K Ex99.1 2026-07-29 acc 0001628280-26-050622 and 10-Q MD&A/segment notes (phase2/data/segment_ebitda.csv). Eliminations = Total less 3 segments
A38: check: segments less total (should be 0) | B38: =B33+B34+B35+B36-B37 | C38: =C33+C34+C35+C36-C37 | D38: =D33+D34+D35+D36-D37 | E38: =E33+E34+E35+E36-E37 | F38: =F33+F34+F35+F36-F37 | G38: =G33+G34+G35+G36-G37 | H38: =H33+H34+H35+H36-H37 | I38: =I33+I34+I35+I36-I37 | ... N38: =N33+N34+N35+N36-N37 | O38: Formula check
A39: Segment-basis EBITDA (Aerospace + Leasing; excl. Corporate and Elims) | B39: =B33+B34 | C39: =C33+C34 | D39: =D33+D34 | E39: =E33+E34 | F39: =F33+F34 | G39: =G33+G34 | H39: =H33+H34 | I39: =I33+I34 | ... N39: =N33+N34 | O39: Formula. Basis used by management guidance (2026: 1,525 = 1,050 + 475)
A40: Aerospace modules produced (units) | I40: 138 | J40: 184 | L40: 228 | N40: 296 | O40: Q2-25 release (184); Q4-25 call (228); Q2-26 call (296); Q1-25 (~138) back-solved from '+33%'. Q3-25 and Q1-26 not found. Call figures are secondary
A41: Aerospace modules incl. Q1-26 estimate (Q1-26 = EBITDA / Q2-26 EBITDA per module) | M41: =ROUND(M33/(N33/N40),0) | N41: =N40 | O41: ASSUMPTION (derived): Q1-26 modules not disclosed in sources; estimated at Q2-26 derived EBITDA/module of 0.84
...

Sheet Quarterly
A1: Quarterly model: Q1'26A, Q2'26A, Q3'26E - Q4'27E (8 quarters, 2 actual)
A2: Forecast cells are formulas on the Drivers tab (selected scenario). Actual columns link to Historical (green). USD m except per-share.
A4: USD m | B4: Q1'26A | C4: Q2'26A | D4: Q3'26E | E4: Q4'26E | F4: Q1'27E | G4: Q2'27E | H4: Q3'27E | I4: Q4'27E | J4: FY2026E | K4: FY2027E | L4: Notes
A5: AEROSPACE
A6: Modules produced / sold (units) | B6: =Historical!$M$41 | C6: =Historical!$N$41 | D6: =Drivers!D$31 | E6: =Drivers!E$31 | F6: =Drivers!F$31 | G6: =Drivers!G$31 | H6: =Drivers!H$31 | I6: =Drivers!I$31 | J6: =SUM(B6:E6) | K6: =SUM(F6:I6) | L6: Q1'26 modules estimated (not disclosed)
A7: Revenue per module ($M) | B7: =IF(B6=0,"",B8/B6) | C7: =IF(C6=0,"",C8/C6) | D7: =Drivers!D$40 | E7: =Drivers!E$40 | F7: =Drivers!F$40 | G7: =Drivers!G$40 | H7: =Drivers!H$40 | I7: =Drivers!I$40 | J7: =IF(J6=0,"",J8/J6) | K7: =IF(K6=0,"",K8/K6)
A8: Aerospace segment revenue | B8: =Historical!$M$14 | C8: =Historical!$N$14 | D8: =D6*D7 | E8: =E6*E7 | F8: =F6*F7 | G8: =G6*G7 | H8: =H6*H7 | I8: =I6*I7 | J8: =SUM(B8:E8) | K8: =SUM(F8:I8)
A9: MRE share of Aerospace revenue | B9: =IF(B8=0,"",B10/B8) | C9: =IF(C8=0,"",C10/C8) | D9: =Drivers!D$51 | E9: =Drivers!E$51 | F9: =Drivers!F$51 | G9: =Drivers!G$51 | H9: =Drivers!H$51 | I9: =Drivers!I$51 | J9: =IF(J8=0,"",J10/J8) | K9: =IF(K8=0,"",K10/K8)
A10: MRE Contract revenue (to 2025 Partnership) | B10: =Historical!$M$7 | C10: =Historical!$N$7 | D10: =D8*D9 | E10: =E8*E9 | F10: =F8*F9 | G10: =G8*G9 | H10: =H8*H9 | I10: =I8*I9 | J10: =SUM(B10:E10) | K10: =SUM(F10:I10)
A11: EBITDA per module ($M) | B11: =IF(B6=0,"",B12/B6) | C11: =IF(C6=0,"",C12/C6) | D11: =Drivers!D$49 | E11: =Drivers!E$49 | F11: =Drivers!F$49 | G11: =Drivers!G$49 | H11: =Drivers!H$49 | I11: =Drivers!I$49 | J11: =IF(J6=0,"",J12/J6) | K11: =IF(K6=0,"",K12/K6)
A12: Aerospace Adj. EBITDA [KEY #1 = modules x EBITDA per module] | B12: =Historical!$M$33 | C12: =Historical!$N$33 | D12: =D6*D11 | E12: =E6*E11 | F12: =F6*F11 | G12: =G6*G11 | H12: =H6*H11 | I12: =I6*I11 | J12: =SUM(B12:E12) | K12: =SUM(F12:I12) | L12: KEY #1. Mgmt FY27 1,400 / Base 1,230
A13: Aerospace EBITDA margin | B13: =IF(B8=0,"",B12/B8) | C13: =IF(C8=0,"",C12/C8) | D13: =D12/D8 | E13: =E12/E8 | F13: =F12/F8 | G13: =G12/G8 | H13: =H12/H8 | I13: =I12/I8 | J13: =IF(J8=0,"",J12/J8) | K13: =IF(K8=0,"",K12/K8)
A14: Aerospace cost of sales (actual; forecast proxy = revenue less EBITDA) | B14: =Historical!$M$17 | C14: =Historical!$N$17 | D14: =D8-D12 | E14: =E8-E12 | F14: =F8-F12 | G14: =G8-G12 | H14: =H8-H12 | I14: =I8-I12 | J14: =SUM(B14:E14) | K14: =SUM(F14:I14)
A15: POWER (J&F JV; pro-rata Adj. EBITDA)
A16: Power units delivered | B16: 0 | C16: 0 | D16: =Drivers!D$68 | E16: =Drivers!E$68 | F16: =Drivers!F$68 | G16: =Drivers!G$68 | H16: =Drivers!H$68 | I16: =Drivers!I$68 | J16: =SUM(B16:E16) | K16: =SUM(F16:I16)
A17: EBITDA per unit ($M) | D17: =Drivers!D$75 | E17: =Drivers!E$75 | F17: =Drivers!F$75 | G17: =Drivers!G$75 | H17: =Drivers!H$75 | I17: =Drivers!I$75
A18: Power Adj. EBITDA [KEY #3 = units x EBITDA per unit] | B18: 0 | C18: 0 | D18: =D16*D17 | E18: =E16*E17 | F18: =F16*F17 | G18: =G16*G17 | H18: =H16*H17 | I18: =I16*I17 | J18: =SUM(B18:E18) | K18: =SUM(F18:I18) | L18: KEY #3. 2026 = 0 (first units 'prudent to expect' 2027)
A19: Power revenue to FTAI (memo, unverified price) | B19: 0 | C19: 0 | D19: =D16*Drivers!$D$77 | E19: =E16*Drivers!$D$77 | F19: =F16*Drivers!$D$77 | G19: =G16*Drivers!$D$77 | H19: =H16*Drivers!$D$77 | I19: =I16*Drivers!$D$77 | J19: =SUM(B19:E19) | K19: =SUM(F19:I19)
A20: LEASING
A21: Leasing book, beginning | B21: =Historical!$L$64 | C21: =B25 | D21: =C25 | E21: =D25 | F21: =E25 | G21: =F25 | H21: =G25 | I21: =H25 | J21: =B21 | K21: =F21 | L21: Q2'26 ending book 1,146.4 is the 6/30/26 balance sheet
A22: less: book value sold (run-off) | D22: =Drivers!D$88 | E22: =Drivers!E$88 | F22: =Drivers!F$88 | G22: =Drivers!G$88 | H22: =Drivers!H$88 | I22: =Drivers!I$88 | J22: =SUM(B22:E22) | K22: =SUM(F22:I22)
A23: less: depreciation on book | D23: =Drivers!$D$129*D21 | E23: =Drivers!$D$129*E21 | F23: =Drivers!$D$129*F21 | G23: =Drivers!$D$129*G21 | H23: =Drivers!$D$129*H21 | I23: =Drivers!$D$129*I21 | J23: =SUM(B23:E23) | K23: =SUM(F23:I23)
A24: plus: leasing equipment acquisitions | B24: =-Historical!$M$54 | C24: =-Historical!$N$54 | D24: =Drivers!D$117 | E24: =Drivers!E$117 | F24: =Drivers!F$117 | G24: =Drivers!G$117 | H24: =Drivers!H$117 | I24: =Drivers!I$117 | J24: =SUM(B24:E24) | K24: =SUM(F24:I24)
A25: Leasing book, end | B25: =Historical!$M$64 | C25: =Historical!$N$64 | D25: =D21-D22-D23+D24 | E25: =E21-E22-E23+E24 | F25: =F21-F22-F23+F24 | G25: =G21-G22-G23+G24 | H25: =H21-H22-H23+H24 | I25: =I21-I22-I23+I24 | J25: =E25 | K25: =I25
A26: Lease EBITDA on beginning book (yield) | D26: =Drivers!$D$91/Drivers!$D$18*D21 | E26: =Drivers!$D$91/Drivers!$D$18*E21 | F26: =Drivers!$D$91/Drivers!$D$18*F21 | G26: =Drivers!$D$91/Drivers!$D$18*G21 | H26: =Drivers!$D$91/Drivers!$D$18*H21 | I26: =Drivers!$D$91/Drivers!$D$18*I21 | J26: =SUM(B26:E26) | K26: =SUM(F26:I26)
A27: Gains on sale (% of book sold) | D27: =Drivers!$D$90*D22 | E27: =Drivers!$D$90*E22 | F27: =Drivers!$D$90*F22 | G27: =Drivers!$D$90*G22 | H27: =Drivers!$D$90*H22 | I27: =Drivers!$D$90*I22 | J27: =SUM(B27:E27) | K27: =SUM(F27:I27)
A28: SCI AUM, end ($M) | C28: =Drivers!C$97 | D28: =Drivers!D$97 | E28: =Drivers!E$97 | F28: =Drivers!F$97 | G28: =Drivers!G$97 | H28: =Drivers!H$97 | I28: =Drivers!I$97 | J28: =E28 | K28: =I28
A29: SCI servicing fees (grow with AUM) | B29: =Historical!$M$74 | C29: =Historical!$N$74 | D29: =Drivers!$D$100/Drivers!$D$18*C28 | E29: =Drivers!$D$100/Drivers!$D$18*D28 | F29: =Drivers!$D$100/Drivers!$D$18*E28 | G29: =Drivers!$D$100/Drivers!$D$18*F28 | H29: =Drivers!$D$100/Drivers!$D$18*G28 | I29: =Drivers!$D$100/Drivers!$D$18*H28 | J29: =SUM(B29:E29) | K29: =SUM(F29:I29)
A30: Pro-rata SCI EBITDA and co-invest returns (non-cash) | B30: =Drivers!$D$152 | C30: =Drivers!$D$152 | D30: =Drivers!D$106 | E30: =Drivers!E$106 | F30: =Drivers!F$106 | G30: =Drivers!G$106 | H30: =Drivers!H$106 | I30: =Drivers!I$106 | J30: =SUM(B30:E30) | K30: =SUM(F30:I30)
A31: Insurance recoveries | D31: =Drivers!D$108 | E31: =Drivers!E$108 | F31: =Drivers!F$108 | G31: =Drivers!G$108 | H31: =Drivers!H$108 | I31: =Drivers!I$108 | J31: =SUM(B31:E31) | K31: =SUM(F31:I31)
A32: Leasing Adj. EBITDA | B32: =Historical!$M$34 | C32: =Historical!$N$34 | D32: =D26+D27+D29+D30+D31 | E32: =E26+E27+E29+E30+E31 | F32: =F26+F27+F29+F30+F31 | G32: =G26+G27+G29+G30+G31 | H32: =H26+H27+H29+H30+H31 | I32: =I26+I27+I29+I30+I31 | J32: =SUM(B32:E32) | K32: =SUM(F32:I32)
A33: Leasing segment revenue | B33: =Historical!$M$15 | C33: =Historical!$N$15 | D33: =D32*Drivers!$D$122 | E33: =E32*Drivers!$D$122 | F33: =F32*Drivers!$D$122 | G33: =G32*Drivers!$D$122 | H33: =H32*Drivers!$D$122 | I33: =I32*Drivers!$D$122 | J33: =SUM(B33:E33) | K33: =SUM(F33:I33)
A34: CORPORATE AND TOTALS
A35: Corporate and Other EBITDA | B35: =Historical!$M$35 | C35: =Historical!$N$35 | D35: =Drivers!D$125 | E35: =Drivers!E$125 | F35: =Drivers!F$125 | G35: =Drivers!G$125 | H35: =Drivers!H$125 | I35: =Drivers!I$125 | J35: =SUM(B35:E35) | K35: =SUM(F35:I35)
A36: Eliminations (profit on sales to 2025 Partnership) | B36: =Historical!$M$36 | C36: =Historical!$N$36 | D36: =-Drivers!$D$127*D10 | E36: =-Drivers!$D$127*E10 | F36: =-Drivers!$D$127*F10 | G36: =-Drivers!$D$127*G10 | H36: =-Drivers!$D$127*H10 | I36: =-Drivers!$D$127*I10 | J36: =SUM(B36:E36) | K36: =SUM(F36:I36)
A37: Total Adjusted EBITDA (company basis) | B37: =B12+B18+B32+B35+B36 | C37: =C12+C18+C32+C35+C36 | D37: =D12+D18+D32+D35+D36 | E37: =E12+E18+E32+E35+E36 | F37: =F12+F18+F32+F35+F36 | G37: =G12+G18+G32+G35+G36 | H37: =H12+H18+H32+H35+H36 | I37: =I12+I18+I32+I35+I36 | J37: =SUM(B37:E37) | K37: =SUM(F37:I37)
A38: Segment-basis EBITDA (Aero + Power + Leasing; guide basis) | B38: =B12+B18+B32 | C38: =C12+C18+C32 | D38: =D12+D18+D32 | E38: =E12+E18+E32 | F38: =F12+F18+F32 | G38: =G12+G18+G32 | H38: =H12+H18+H32 | I38: =I12+I18+I32 | J38: =SUM(B38:E38) | K38: =SUM(F38:I38) | L38: Ties to guide: FY26 1,525 / FY27 2,300 in Mgmt Guide scenario
A39: Total revenues | B39: =Historical!$M$12 | C39: =Historical!$N$12 | D39: =D8+D19+D33 | E39: =E8+E19+E33 | F39: =F8+F19+F33 | G39: =G8+G19+G33 | H39: =H8+H19+H33 | I39: =I8+I19+I33 | J39: =SUM(B39:E39) | K39: =SUM(F39:I39)
A40: Adj. EBITDA margin on revenue | B40: =IF(B39=0,"",B37/B39) | C40: =IF(C39=0,"",C37/C39) | D40: =D37/D39 | E40: =E37/E39 | F40: =F37/F39 | G40: =G37/G39 | H40: =H37/H39 | I40: =I37/I39 | J40: =IF(J39=0,"",J37/J39) | K40: =IF(K39=0,"",K37/K39)
A41: EPS BRIDGE
...

Sheet Annual
A1: Annual model: FY2023A - FY2025A history, FY2026E - FY2030E projections (5 years)
A2: FY26 and FY27 are summed from Quarterly; FY28-FY30 are driven by annual growth, margin-scale (capped) and unit drivers on the Drivers tab. USD m except per-share.
A4: USD m | B4: FY2023A | C4: FY2024A | D4: FY2025A | E4: FY2026E | F4: FY2027E | G4: FY2028E | H4: FY2029E | I4: FY2030E | J4: Notes
A5: AEROSPACE
A6: Modules produced / sold (units) | E6: =SUM(Quarterly!B6:E6) | F6: =SUM(Quarterly!F6:I6) | G6: =F6*(1+Drivers!J$38) | H6: =G6*(1+Drivers!K$38) | I6: =H6*(1+Drivers!L$38)
A7: Revenue per module ($M) | E7: =IF(E6=0,"",E8/E6) | F7: =IF(F6=0,"",F8/F6) | G7: =F7*(1+Drivers!J$42) | H7: =G7*(1+Drivers!K$42) | I7: =H7*(1+Drivers!L$42)
A8: Aerospace segment revenue | B8: =Historical!$B$14 | C8: =Historical!$C$14 | D8: =Historical!$D$14 | E8: =SUM(Quarterly!B8:E8) | F8: =SUM(Quarterly!F8:I8) | G8: =G6*G7 | H8: =H6*H7 | I8: =I6*I7
A9: MRE share of Aerospace revenue | D9: =IF(D8=0,"",D10/D8) | E9: =IF(E8=0,"",E10/E8) | F9: =IF(F8=0,"",F10/F8) | G9: =Drivers!J$51 | H9: =Drivers!K$51 | I9: =Drivers!L$51
A10: MRE Contract revenue (to 2025 Partnership) | D10: =Historical!$D$7 | E10: =SUM(Quarterly!B10:E10) | F10: =SUM(Quarterly!F10:I10) | G10: =G8*G9 | H10: =H8*H9 | I10: =I8*I9
A11: EBITDA per module ($M) | E11: =IF(E6=0,"",E12/E6) | F11: =IF(F6=0,"",F12/F6) | G11: =G12/G6 | H11: =H12/H6 | I11: =I12/I6
A12: Aerospace Adj. EBITDA [KEY #1 = modules x EBITDA per module] | B12: =Historical!$B$33 | C12: =Historical!$C$33 | D12: =Historical!$D$33 | E12: =SUM(Quarterly!B12:E12) | F12: =SUM(Quarterly!F12:I12) | G12: =G8*G13 | H12: =H8*H13 | I12: =I8*I13 | J12: FY26/27 = sum of Quarterly. History: segment Adj. EBITDA
A13: Aerospace EBITDA margin | B13: =IF(B8=0,"",B12/B8) | C13: =IF(C8=0,"",C12/C8) | D13: =IF(D8=0,"",D12/D8) | E13: =IF(E8=0,"",E12/E8) | F13: =IF(F8=0,"",F12/F8) | G13: =MIN(Drivers!D$58,F13+Drivers!$D$60*Drivers!J$38) | H13: =MIN(Drivers!D$58,G13+Drivers!$D$60*Drivers!K$38) | I13: =MIN(Drivers!D$58,H13+Drivers!$D$60*Drivers!L$38) | J13: FY28+: margin = MIN(cap, prior + elasticity x volume growth): economies of scale up to a cap
A14: Aerospace cost of sales (actual; forecast proxy = revenue less EBITDA) | B14: =Historical!$B$17 | C14: =Historical!$C$17 | D14: =Historical!$D$17 | E14: =SUM(Quarterly!B14:E14) | F14: =SUM(Quarterly!F14:I14) | G14: =G8-G12 | H14: =H8-H12 | I14: =I8-I12
A15: POWER (J&F JV; pro-rata Adj. EBITDA)
A16: Power units delivered | E16: =SUM(Quarterly!B16:E16) | F16: =SUM(Quarterly!F16:I16) | G16: =Drivers!J$68 | H16: =Drivers!K$68 | I16: =Drivers!L$68
A17: EBITDA per unit ($M) | G17: =Drivers!J$75 | H17: =Drivers!K$75 | I17: =Drivers!L$75
A18: Power Adj. EBITDA [KEY #3 = units x EBITDA per unit] | E18: =SUM(Quarterly!B18:E18) | F18: =SUM(Quarterly!F18:I18) | G18: =G16*G17 | H18: =H16*H17 | I18: =I16*I17
A19: Power revenue to FTAI (memo, unverified price) | E19: =SUM(Quarterly!B19:E19) | F19: =SUM(Quarterly!F19:I19) | G19: =G16*Drivers!$D$77 | H19: =H16*Drivers!$D$77 | I19: =I16*Drivers!$D$77
A20: LEASING
A21: Leasing book, beginning | E21: =Quarterly!B21 | F21: =Quarterly!F21 | G21: =F25 | H21: =G25 | I21: =H25
A22: less: book value sold (run-off) | E22: =SUM(Quarterly!B22:E22) | F22: =SUM(Quarterly!F22:I22) | G22: =Drivers!J$88 | H22: =Drivers!K$88 | I22: =Drivers!L$88
A23: less: depreciation on book | E23: =SUM(Quarterly!B23:E23) | F23: =SUM(Quarterly!F23:I23) | G23: =Drivers!$D$129*Drivers!$D$18*G21 | H23: =Drivers!$D$129*Drivers!$D$18*H21 | I23: =Drivers!$D$129*Drivers!$D$18*I21
A24: plus: leasing equipment acquisitions | E24: =SUM(Quarterly!B24:E24) | F24: =SUM(Quarterly!F24:I24) | G24: =Drivers!J$117 | H24: =Drivers!K$117 | I24: =Drivers!L$117
A25: Leasing book, end | B25: =Historical!$B$64 | C25: =Historical!$C$64 | D25: =Historical!$D$64 | E25: =Quarterly!E25 | F25: =Quarterly!I25 | G25: =G21-G22-G23+G24 | H25: =H21-H22-H23+H24 | I25: =I21-I22-I23+I24
A26: Lease EBITDA on beginning book (yield) | E26: =SUM(Quarterly!B26:E26) | F26: =SUM(Quarterly!F26:I26)
A27: Gains on sale (% of book sold) | B27: =Historical!$B$46 | C27: =Historical!$C$46 | D27: =Historical!$D$46 | E27: =SUM(Quarterly!B27:E27) | F27: =SUM(Quarterly!F27:I27) | G27: =Drivers!$D$90*G22 | H27: =Drivers!$D$90*H22 | I27: =Drivers!$D$90*I22
A28: SCI AUM, end ($M) | E28: =Quarterly!E28 | F28: =Quarterly!I28 | G28: =Drivers!J$97 | H28: =Drivers!K$97 | I28: =Drivers!L$97
A29: SCI servicing fees (grow with AUM) | E29: =SUM(Quarterly!B29:E29) | F29: =SUM(Quarterly!F29:I29)
A30: Pro-rata SCI EBITDA and co-invest returns (non-cash) | E30: =SUM(Quarterly!B30:E30) | F30: =SUM(Quarterly!F30:I30) | G30: =G32*F30/F32 | H30: =H32*G30/G32 | I30: =I32*H30/H32
A31: Insurance recoveries | E31: =SUM(Quarterly!B31:E31) | F31: =SUM(Quarterly!F31:I31)
A32: Leasing Adj. EBITDA | B32: =Historical!$B$34 | C32: =Historical!$C$34 | D32: =Historical!$D$34 | E32: =SUM(Quarterly!B32:E32) | F32: =SUM(Quarterly!F32:I32) | G32: =F32*(1+Drivers!J$115) | H32: =G32*(1+Drivers!K$115) | I32: =H32*(1+Drivers!L$115)
A33: Leasing segment revenue | B33: =Historical!$B$15 | C33: =Historical!$C$15 | D33: =Historical!$D$15 | E33: =SUM(Quarterly!B33:E33) | F33: =SUM(Quarterly!F33:I33) | G33: =G32*Drivers!$D$122 | H33: =H32*Drivers!$D$122 | I33: =I32*Drivers!$D$122
A34: CORPORATE AND TOTALS
A35: Corporate and Other EBITDA | B35: =Historical!$B$35 | C35: =Historical!$C$35 | D35: =Historical!$D$35 | E35: =SUM(Quarterly!B35:E35) | F35: =SUM(Quarterly!F35:I35) | G35: =F35*(1+Drivers!J$125) | H35: =G35*(1+Drivers!K$125) | I35: =H35*(1+Drivers!L$125)
A36: Eliminations (profit on sales to 2025 Partnership) | B36: =Historical!$B$36 | C36: =Historical!$C$36 | D36: =Historical!$D$36 | E36: =SUM(Quarterly!B36:E36) | F36: =SUM(Quarterly!F36:I36) | G36: =-Drivers!$D$127*G10 | H36: =-Drivers!$D$127*H10 | I36: =-Drivers!$D$127*I10
A37: Total Adjusted EBITDA (company basis) | B37: =B12+B32+B35+B36 | C37: =C12+C32+C35+C36 | D37: =D12+D32+D35+D36 | E37: =SUM(Quarterly!B37:E37) | F37: =SUM(Quarterly!F37:I37) | G37: =G12+G18+G32+G35+G36 | H37: =H12+H18+H32+H35+H36 | I37: =I12+I18+I32+I35+I36
A38: Segment-basis EBITDA (Aero + Power + Leasing; guide basis) | B38: =B12+B32 | C38: =C12+C32 | D38: =D12+D32 | E38: =SUM(Quarterly!B38:E38) | F38: =SUM(Quarterly!F38:I38) | G38: =G12+G18+G32 | H38: =H12+H18+H32 | I38: =I12+I18+I32 | J38: FY26 guide 1,525; FY27 guide 2,300
A39: Total revenues | B39: =Historical!$B$12 | C39: =Historical!$C$12 | D39: =Historical!$D$12 | E39: =SUM(Quarterly!B39:E39) | F39: =SUM(Quarterly!F39:I39) | G39: =G8+G19+G33 | H39: =H8+H19+H33 | I39: =I8+I19+I33
A40: Adj. EBITDA margin on revenue | B40: =IF(B39=0,"",B37/B39) | C40: =IF(C39=0,"",C37/C39) | D40: =IF(D39=0,"",D37/D39) | E40: =IF(E39=0,"",E37/E39) | F40: =IF(F39=0,"",F37/F39) | G40: =G37/G39 | H40: =H37/H39 | I40: =I37/I39
A41: EPS BRIDGE
...

Sheet FCF_Quality
A1: FCF quality: the thesis tab (three ways to count cash)
A2: (a) company 'Adjusted FCF'; (b) GAAP CFO + CFI; (c) clean CFO + CFI excluding seed-sale proceeds and insurance recoveries. Projection columns follow the selected scenario.
A4: USD m | B4: FY2023A | C4: FY2024A | D4: FY2025A | E4: FY2026E | F4: FY2027E | G4: FY2028E | H4: FY2029E | I4: FY2030E | J4: Notes
A5: Three definitions by year
A6: Reported CFO (history) / n.a. in projections (model builds CFO + CFI combined) | B6: =Historical!$B$48 | C6: =Historical!$C$48 | D6: =Historical!$D$48
A7: Reported CFI (history) | B7: =Historical!$B$49 | C7: =Historical!$C$49 | D7: =Historical!$D$49
A8: (b) GAAP CFO + CFI | B8: =Annual!B71 | C8: =Annual!C71 | D8: =Annual!D71 | E8: =Annual!E71 | F8: =Annual!F71 | G8: =Annual!G71 | H8: =Annual!H71 | I8: =Annual!I71 | J8: FY25 CFO -310.7 and CFI +723.3 tie to filings
A9: less: seed-sale proceeds to 2025 Partnership / SCI | B9: =-N(Annual!B72) | C9: =-N(Annual!C72) | D9: =-N(Annual!D72) | E9: =-N(Annual!E72) | F9: =-N(Annual!F72) | G9: =-N(Annual!G72) | H9: =-N(Annual!H72) | I9: =-N(Annual!I72)
A10: less: insurance proceeds (Russia) | B10: =-N(Annual!B73) | C10: =-N(Annual!C73) | D10: =-N(Annual!D73) | E10: =-N(Annual!E73) | F10: =-N(Annual!F73) | G10: =-N(Annual!G73) | H10: =-N(Annual!H73) | I10: =-N(Annual!I73)
A11: (c) Clean CFO + CFI | B11: =B8+B9+B10 | C11: =C8+C9+C10 | D11: =D8+D9+D10 | E11: =E8+E9+E10 | F11: =F8+F9+F10 | G11: =G8+G9+G10 | H11: =H8+H9+H10 | I11: =I8+I9+I10
A12: (a) Company-defined Adjusted FCF | D12: =Annual!D75 | E12: =Annual!E75 | F12: =Annual!F75 | G12: =Annual!G75 | H12: =Annual!H75 | I12: =Annual!I75 | J12: FY25 724 reported (call). FY26 = 1H26 reported 255 + 2H26 model on FY25-style add-backs
A13: Gap: (a) less (b) = add-backs of growth investment | D13: =D12-D8 | E13: =E12-E8 | F13: =F12-F8 | G13: =G12-G8 | H13: =H12-H8 | I13: =I12-I8
A14: Gap: (a) less (c) | D14: =D12-D11 | E14: =E12-E11 | F14: =F12-F11 | G14: =G12-G11 | H14: =H12-H11 | I14: =I12-I11
A15: Total Adjusted EBITDA (company basis) | B15: =Annual!B37 | C15: =Annual!C37 | D15: =Annual!D37 | E15: =Annual!E37 | F15: =Annual!F37 | G15: =Annual!G37 | H15: =Annual!H37 | I15: =Annual!I37
A16: (b) / Adjusted EBITDA | B16: =B8/B15 | C16: =C8/C15 | D16: =D8/D15 | E16: =E8/E15 | F16: =F8/F15 | G16: =G8/G15 | H16: =H8/H15 | I16: =I8/I15
A17: (c) / Adjusted EBITDA | B17: =B11/B15 | C17: =C11/C15 | D17: =D11/D15 | E17: =E11/E15 | F17: =F11/F15 | G17: =G11/G15 | H17: =H11/H15 | I17: =I11/I15
A18: (a) / Adjusted EBITDA | D18: =D12/D15 | E18: =E12/E15 | F18: =F12/F15 | G18: =G12/G15 | H18: =H12/H15 | I18: =I12/I15
A19: (a) yield on market cap | D19: =D12/Drivers!$D$182 | E19: =E12/Drivers!$D$182 | F19: =F12/Drivers!$D$182 | G19: =G12/Drivers!$D$182 | H19: =H12/Drivers!$D$182 | I19: =I12/Drivers!$D$182 | J19: Management guide 878 / market cap 18,430 = 4.8% (vs peers 2.4-3.3%)
A20: (c) yield on market cap | B20: =B11/Drivers!$D$182 | C20: =C11/Drivers!$D$182 | D20: =D11/Drivers!$D$182 | E20: =E11/Drivers!$D$182 | F20: =F11/Drivers!$D$182 | G20: =G11/Drivers!$D$182 | H20: =H11/Drivers!$D$182 | I20: =I11/Drivers!$D$182
A22: SCI: pro-rata EBITDA counted in Adj. EBITDA vs cash actually distributed
A23: Pro-rata SCI EBITDA and co-invest returns (non-cash) | E23: =Annual!E30 | F23: =Annual!F30 | G23: =Annual!G30 | H23: =Annual!H30 | I23: =Annual!I30 | J23: FY26 includes 1H26 assumed 28.0/qtr (call 35 less 7.0 fees)
A24: Cash distributions from SCI (return of capital, CFI) | D24: =Historical!$D$57 | E24: =Historical!$M$57+Historical!$N$57+SUM(Quarterly!D59:E59) | F24: =Annual!F59 | G24: =Annual!G59 | H24: =Annual!H59 | I24: =Annual!I59 | J24: FY25 27.1 'return of capital' (carried from prior research). Pro-rata EBITDA for FY25 not disclosed by component
A25: Gap: EBITDA counted but not received in cash | E25: =E23-E24 | F25: =F23-F24 | G25: =G23-G24 | H25: =H23-H24 | I25: =I23-I24
A26: Cash distributions as % of pro-rata EBITDA | E26: =E24/E23 | F26: =F24/F23 | G26: =G24/G23 | H26: =H24/H23 | I26: =I24/I23
A28: FY25 reconciliation: $724M Adjusted FCF to $412.6M CFO + CFI
A29: Company Adjusted FCF, FY25 | B29: =Historical!$D$60 | J29: Q4-25 call (Motley Fool transcript 2026-02-26), secondary
A30: less: GAAP CFO + CFI | B30: =-Historical!$D$50 | J30: CFO -310.7 + CFI +723.3 (10-K FY25)
A31: Gap to explain | B31: =B29+B30
A32: named by CFO: increase in SCI co-investment | B32: 52 | J32: Q4-25 call: 'further adjusted for 3 key investments'
A33: named by CFO: Power turbines | B33: 150 | J33: Q4-25 call
A34: named by CFO: hot-section parts | B34: 50 | J34: Q4-25 call
A35: subtotal named by the CFO | B35: =SUM(B32:B34)
A36: residual: INFERRED (probably acquisitions 49.1 + ~10 JV item), NOT CONFIRMED | B36: =B31-B35
A37: of the gap, inventory-type purchases (Power turbines + hot-section parts) | B37: =B33+B34 | J37: ~$200M of the add-backs are the same inventory-type items that drive negative GAAP CFO
A39: 1H26: what cash looks like without the one-offs
A40: 1H26 CFO | B40: =Historical!$M$48+Historical!$N$48 | J40: -160.1 + -105.2 = -265.3
A41: 1H26 CFI | B41: =Historical!$M$49+Historical!$N$49 | J41: 317.0 + 198.7 = 515.7
A42: 1H26 CFO + CFI | B42: =B40+B41 | J42: 250.4
A43: less: seed-sale proceeds (15 aircraft to 2025 Partnership) | B43: =-(Historical!$M$52+Historical!$N$52) | J43: 175.7; 10-Q: sales 'non-recurring in nature'
A44: less: Russia insurance proceeds | B44: =-(Historical!$M$53+Historical!$N$53) | J44: 48.3 (CFI proceeds, not the CFO gain add-back of 49.5)
...

Sheet Valuation
A1: Valuation: SOTP, P/E cross-check, DCF, blended price target
A2: SOTP is live for all four scenarios (Leasing at book). P/E, DCF and blended are live for the SELECTED scenario; the snapshot block stores all four (regenerated by build_model.py).
A4: 1. Market data and equity bridge
A5: Share price 10/6/26 ($) | B5: =Drivers!$D$180
A6: Shares (M) | B6: =Drivers!$D$181
A7: Market cap (stockanalysis) | B7: =Drivers!$D$182
A8: Enterprise value (stockanalysis) | B8: =Drivers!$D$183
A9: Net debt per stockanalysis (EV - market cap) | B9: =Drivers!$D$184
A10: Net debt per balance sheet 6/30/26 (debt 3,496.4 - cash 337.2) | B10: =Drivers!$D$185 | G10: Used in all bridges
A11: Reconciliation difference | B11: =B10-B9 | G11: Within ~1: stockanalysis uses face debt 3,500
A12: Preferred at liquidation (deducted) | B12: =Drivers!$D$187*Drivers!$D$186
A13: Leasing book: equipment net 1,146.4 + SCI I stake 365.5 | B13: =Drivers!$D$188
A15: 2. Sum-of-the-parts on 2027E (TTM peer multiples applied to 2027E: 2027 is the trailing year at a 12-month horizon)
A16: USD m | B16: Bear | C16: Base | D16: Bull | E16: Mgmt Guide | F16: Selected | G16: Notes
A17: 2027E Aerospace EBITDA | B17: =Drivers!$D$263 | C17: =Drivers!$E$263 | D17: =Drivers!$F$263 | E17: =Drivers!$G$263 | F17: =INDEX(B17:E17,Drivers!$E$4)
A18: x multiple | B18: =Drivers!D$190 | C18: =Drivers!D$191 | D18: =Drivers!D$192 | E18: =Drivers!D$193 | F18: =INDEX(B18:E18,Drivers!$E$4)
A19: Aerospace EV | B19: =B17*B18 | C19: =C17*C18 | D19: =D17*D18 | E19: =E17*E18 | F19: =INDEX(B19:E19,Drivers!$E$4)
A20: 2027E Power EBITDA (pro-rata) | B20: =Drivers!$D$264 | C20: =Drivers!$E$264 | D20: =Drivers!$F$264 | E20: =Drivers!$G$264 | F20: =INDEX(B20:E20,Drivers!$E$4)
A21: x multiple | B21: =Drivers!D$197 | C21: =Drivers!D$198 | D21: =Drivers!D$199 | E21: =Drivers!D$200 | F21: =INDEX(B21:E21,Drivers!$E$4)
A22: Power EV | B22: =B20*B21 | C22: =C20*C21 | D22: =D20*D21 | E22: =E20*E21 | F22: =INDEX(B22:E22,Drivers!$E$4)
A23: Leasing book value | B23: =Drivers!$D$188 | C23: =Drivers!$D$188 | D23: =Drivers!$D$188 | E23: =Drivers!$D$188 | F23: =INDEX(B23:E23,Drivers!$E$4)
A24: x book multiple | B24: =Drivers!D$204 | C24: =Drivers!D$205 | D24: =Drivers!D$206 | E24: =Drivers!D$207 | F24: =INDEX(B24:E24,Drivers!$E$4) | G24: Leasing valued at book because the book is being sold down and EBITDA is gain-heavy
A25: Leasing value | B25: =B23*B24 | C25: =C23*C24 | D25: =D23*D24 | E25: =E23*E24 | F25: =INDEX(B25:E25,Drivers!$E$4)
A26: Corporate costs capitalised (2027E x blended multiple) | B26: =Drivers!$D$210*SUM(Drivers!F$125:I$125)*B35 | C26: =Drivers!$D$210*SUM(Drivers!F$125:I$125)*C35 | D26: =Drivers!$D$210*SUM(Drivers!F$125:I$125)*D35 | E26: =Drivers!$D$210*SUM(Drivers!F$125:I$125)*E35 | F26: =INDEX(B26:E26,Drivers!$E$4) | G26: 2027E corporate costs x blended Aero+Power multiple (memo row below)
A27: Enterprise value | B27: =B19+B22+B25+B26 | C27: =C19+C22+C25+C26 | D27: =D19+D22+D25+D26 | E27: =E19+E22+E25+E26 | F27: =INDEX(B27:E27,Drivers!$E$4)
A28: less: net debt | B28: =-Drivers!$D$185 | C28: =-Drivers!$D$185 | D28: =-Drivers!$D$185 | E28: =-Drivers!$D$185 | F28: =INDEX(B28:E28,Drivers!$E$4)
A29: less: preferred | B29: =-Drivers!$D$187*Drivers!$D$186 | C29: =-Drivers!$D$187*Drivers!$D$186 | D29: =-Drivers!$D$187*Drivers!$D$186 | E29: =-Drivers!$D$187*Drivers!$D$186 | F29: =INDEX(B29:E29,Drivers!$E$4)
A30: Equity value | B30: =B27+B28+B29 | C30: =C27+C28+C29 | D30: =D27+D28+D29 | E30: =E27+E28+E29 | F30: =INDEX(B30:E30,Drivers!$E$4)
A31: SOTP value per share ($) | B31: =B30/Drivers!$D$181 | C31: =C30/Drivers!$D$181 | D31: =D30/Drivers!$D$181 | E31: =E30/Drivers!$D$181 | F31: =INDEX(B31:E31,Drivers!$E$4)
A32: Spec / thesis target ($) | B32: 115 | C32: 172 | D32: 280 | G32: thesis.md section 2 (Bear ~115, Base ~172, Bull ~280); thesis excludes preferred and uses book ~1.5B
A33: Difference vs target ($) | B33: =B36-B32 | C33: =C36-C32 | D33: =D36-D32
A34: Upside vs current price | B34: =B31/Drivers!$D$180-1 | C34: =C31/Drivers!$D$180-1 | D34: =D31/Drivers!$D$180-1 | E34: =E31/Drivers!$D$180-1 | F34: =INDEX(B34:E34,Drivers!$E$4)
A35: Memo: blended Aero+Power multiple | B35: =(B19+B22)/(B17+B20) | C35: =(C19+C22)/(C17+C20) | D35: =(D19+D22)/(D17+D20) | E35: =(E19+E22)/(E17+E20)
A36: Memo: SOTP value/share EXCLUDING corporate costs (ties to thesis.md v0.2 targets) ($) | B36: =B31-B26/Drivers!$D$181 | C36: =C31-C26/Drivers!$D$181 | D36: =D31-D26/Drivers!$D$181 | E36: =E31-E26/Drivers!$D$181 | G36: Headline SOTP includes corporate costs. This memo excludes them, for comparison with the thesis.md v0.2 targets
A38: 3. Forward P/E cross-check (selected scenario)
A39: Model FY2027E diluted EPS ($) | B39: =Annual!F54
A40: at low P/E | B40: =B39*Drivers!$D$211
A41: at midpoint P/E | B41: =B39*AVERAGE(Drivers!$D$211,Drivers!$D$212)
A42: at high P/E | B42: =B39*Drivers!$D$212
A43: Consensus FY2027E EPS implied (price / 20.2x) ($) | B43: =Drivers!$D$214 | G43: CAVEAT: stockanalysis forward P/E 20.2x conflicts with its own FY26 EPS (30.8x); the $8.87 is an implied, not published, figure
...

Sheet Bridge
A1: Bridge: Management guide ($2,300M 2027E EBITDA) to our Base case
A2: Live formulas independent of the scenario selector (read the scenario engine and SOTP columns). Leasing is valued at book in the SOTP, so its EBITDA gap lowers EPS and FCF but not SOTP value.
A4: Segment (2027E) | B4: Mgmt Guide EBITDA | C4: Our Base EBITDA | D4: Delta EBITDA | E4: Multiple (Base) | F4: Value impact ($/share) | G4: Notes
A5: Aerospace | B5: =Drivers!$G$263 | C5: =Drivers!$E$263 | D5: =C5-B5 | E5: =Drivers!D$191 | F5: =D5*E5/Drivers!$D$181
A6: Power | B6: =Drivers!$G$264 | C6: =Drivers!$E$264 | D6: =C6-B6 | E6: =Drivers!D$198 | F6: =D6*E6/Drivers!$D$181
A7: Leasing | B7: =Drivers!$G$265 | C7: =Drivers!$E$265 | D7: =C7-B7 | E7: book | F7: 0 | G7: Valued at book: EBITDA gap hits EPS/FCF (see bottom), not SOTP. Guide equals Bull on Leasing
A8: Total 2027E segment EBITDA | B8: =SUM(B5:B7) | C8: =SUM(C5:C7) | D8: =SUM(D5:D7) | F8: =SUM(F5:F7)
A10: Value per share: guide to our Base (SOTP)
A11: SOTP value per share at the Mgmt guide ($) | B11: =Valuation!E31
A12: less: Aerospace EBITDA shortfall impact | B12: =F5
A13: less: Power EBITDA shortfall impact | B13: =F6
A14: less: Leasing EBITDA shortfall impact (valued at book) | B14: =F7
A15: Our Base SOTP value per share ($) | B15: =SUM(B11:B14)
A16: check vs Valuation tab Base SOTP (should be 0) | B16: =B15-Valuation!C31
A18: EBITDA waterfall data (for chart): 2027E segment EBITDA, Mgmt guide to Base
A19: Step | B19: Invisible base | C19: Amount
A20: Mgmt guide | B20: 0 | C20: =B8
A21: Aerospace | B21: =B8+D5 | C21: =-D5
A22: Power | B22: =B8+D5+D6 | C22: =-D6
A23: Leasing | B23: =C8 | C23: =-D7
A24: Our Base | B24: 0 | C24: =C8
A33: From the guide to our numbers (snapshot values, all four scenarios)
A34: Metric | B34: Bear | C34: Base | D34: Bull | E34: Mgmt Guide
A35: FY27E total Adj. EBITDA (company basis) | B35: =Valuation!B87 | C35: =Valuation!C87 | D35: =Valuation!D87 | E35: =Valuation!E87
A36: FY27E diluted EPS ($) | B36: =Valuation!B89 | C36: =Valuation!C89 | D36: =Valuation!D89 | E36: =Valuation!E89
A37: SOTP value per share ($) | B37: =Valuation!B90 | C37: =Valuation!C90 | D37: =Valuation!D90 | E37: =Valuation!E90
A38: P/E value per share ($) | B38: =Valuation!B91 | C38: =Valuation!C91 | D38: =Valuation!D91 | E38: =Valuation!E91
A39: DCF value per share ($) | B39: =Valuation!B92 | C39: =Valuation!C92 | D39: =Valuation!D92 | E39: =Valuation!E92
A40: Blended value per share ($) | B40: =Valuation!B93 | C40: =Valuation!C93 | D40: =Valuation!D93 | E40: =Valuation!E93
A42: Second bridge: Street mean PT (~$330, methodology not public) to our price target (narrative table)
A43: Step | B43: $/share | C43: Explanation
A44: Street mean price target (7 dated post-June PTs) | B44: =Drivers!$D$215 | C44: Mean of 290/300/310/350/360/375/325. All Buy-rated; methodology not public
A45: SOTP at the full 2027 guide (our multiples) | B45: =B11 | C45: What management's $2.3B is worth on our peer-based multiples and book-value Leasing
A46: Street premium to guide-SOTP: not explained by any public methodology | B46: =B45-B44 | C46: Implies a premium multiple, 2028+ growth, or Power/SCI franchise value beyond the 2027 guide. Cannot be reproduced from sourced data
A47: Our haircut: guide to Base EBITDA (Aerospace volume, Power timing, Leasing run-rate) | B47: =B15-B11 | C47: Aerospace 1,500 vs 1,700 modules; Power 44 vs 60 units; Leasing at Q2 run-rate plus partial SCI II
A48: Our Base SOTP | B48: =B15
A49: Our probability-weighted blended value | B49: =Valuation!B98 | C49: SOTP / P/E / DCF blend, weighted over Bear/Base/Bull/Mgmt scenarios
A50: Total gap: Street mean PT to our probability-weighted value | B50: =B49-B44

Sheet Sensitivity
A1: Sensitivity: explicit formula grids (Excel Data Tables are not available from openpyxl)
A2: Grids 1-2 use the Base scenario's other segments and the SOTP bridge. Grid 3 recomputes FY26 clean FCF analytically around the selected scenario. Green = above current price (grids 1-2) / above zero (grid 3); red = below.
A4: Grid 1: SOTP value per share ($): 2027E Aerospace EBITDA (rows) x Aerospace EV/EBITDA multiple (columns); Base Power and Leasing
A5: Aerospace EBITDA ($M) \ multiple | B5: 10 | C5: 11.7 | D5: 13 | E5: 14.5 | F5: 16 | G5: 18
A6: 900 | B6: =($A6*B$5+Drivers!$E$264*Drivers!D$198+Drivers!$D$188*Drivers!D$205-(Drivers!$D$185+Drivers!$D$187*Drivers!$D$186))/Drivers!$D$181 | C6: =($A6*C$5+Drivers!$E$264*Drivers!D$198+Drivers!$D$188*Drivers!D$205-(Drivers!$D$185+Drivers!$D$187*Drivers!$D$186))/Drivers!$D$181 | D6: =($A6*D$5+Drivers!$E$264*Drivers!D$198+Drivers!$D$188*Drivers!D$205-(Drivers!$D$185+Drivers!$D$187*Drivers!$D$186))/Drivers!$D$181 | E6: =($A6*E$5+Drivers!$E$264*Drivers!D$198+Drivers!$D$188*Drivers!D$205-(Drivers!$D$185+Drivers!$D$187*Drivers!$D$186))/Drivers!$D$181 | F6: =($A6*F$5+Drivers!$E$264*Drivers!D$198+Drivers!$D$188*Drivers!D$205-(Drivers!$D$185+Drivers!$D$187*Drivers!$D$186))/Drivers!$D$181 | G6: =($A6*G$5+Drivers!$E$264*Drivers!D$198+Drivers!$D$188*Drivers!D$205-(Drivers!$D$185+Drivers!$D$187*Drivers!$D$186))/Drivers!$D$181
A7: 1050 | B7: =($A7*B$5+Drivers!$E$264*Drivers!D$198+Drivers!$D$188*Drivers!D$205-(Drivers!$D$185+Drivers!$D$187*Drivers!$D$186))/Drivers!$D$181 | C7: =($A7*C$5+Drivers!$E$264*Drivers!D$198+Drivers!$D$188*Drivers!D$205-(Drivers!$D$185+Drivers!$D$187*Drivers!$D$186))/Drivers!$D$181 | D7: =($A7*D$5+Drivers!$E$264*Drivers!D$198+Drivers!$D$188*Drivers!D$205-(Drivers!$D$185+Drivers!$D$187*Drivers!$D$186))/Drivers!$D$181 | E7: =($A7*E$5+Drivers!$E$264*Drivers!D$198+Drivers!$D$188*Drivers!D$205-(Drivers!$D$185+Drivers!$D$187*Drivers!$D$186))/Drivers!$D$181 | F7: =($A7*F$5+Drivers!$E$264*Drivers!D$198+Drivers!$D$188*Drivers!D$205-(Drivers!$D$185+Drivers!$D$187*Drivers!$D$186))/Drivers!$D$181 | G7: =($A7*G$5+Drivers!$E$264*Drivers!D$198+Drivers!$D$188*Drivers!D$205-(Drivers!$D$185+Drivers!$D$187*Drivers!$D$186))/Drivers!$D$181
A8: 1150 | B8: =($A8*B$5+Drivers!$E$264*Drivers!D$198+Drivers!$D$188*Drivers!D$205-(Drivers!$D$185+Drivers!$D$187*Drivers!$D$186))/Drivers!$D$181 | C8: =($A8*C$5+Drivers!$E$264*Drivers!D$198+Drivers!$D$188*Drivers!D$205-(Drivers!$D$185+Drivers!$D$187*Drivers!$D$186))/Drivers!$D$181 | D8: =($A8*D$5+Drivers!$E$264*Drivers!D$198+Drivers!$D$188*Drivers!D$205-(Drivers!$D$185+Drivers!$D$187*Drivers!$D$186))/Drivers!$D$181 | E8: =($A8*E$5+Drivers!$E$264*Drivers!D$198+Drivers!$D$188*Drivers!D$205-(Drivers!$D$185+Drivers!$D$187*Drivers!$D$186))/Drivers!$D$181 | F8: =($A8*F$5+Drivers!$E$264*Drivers!D$198+Drivers!$D$188*Drivers!D$205-(Drivers!$D$185+Drivers!$D$187*Drivers!$D$186))/Drivers!$D$181 | G8: =($A8*G$5+Drivers!$E$264*Drivers!D$198+Drivers!$D$188*Drivers!D$205-(Drivers!$D$185+Drivers!$D$187*Drivers!$D$186))/Drivers!$D$181
A9: 1230 | B9: =($A9*B$5+Drivers!$E$264*Drivers!D$198+Drivers!$D$188*Drivers!D$205-(Drivers!$D$185+Drivers!$D$187*Drivers!$D$186))/Drivers!$D$181 | C9: =($A9*C$5+Drivers!$E$264*Drivers!D$198+Drivers!$D$188*Drivers!D$205-(Drivers!$D$185+Drivers!$D$187*Drivers!$D$186))/Drivers!$D$181 | D9: =($A9*D$5+Drivers!$E$264*Drivers!D$198+Drivers!$D$188*Drivers!D$205-(Drivers!$D$185+Drivers!$D$187*Drivers!$D$186))/Drivers!$D$181 | E9: =($A9*E$5+Drivers!$E$264*Drivers!D$198+Drivers!$D$188*Drivers!D$205-(Drivers!$D$185+Drivers!$D$187*Drivers!$D$186))/Drivers!$D$181 | F9: =($A9*F$5+Drivers!$E$264*Drivers!D$198+Drivers!$D$188*Drivers!D$205-(Drivers!$D$185+Drivers!$D$187*Drivers!$D$186))/Drivers!$D$181 | G9: =($A9*G$5+Drivers!$E$264*Drivers!D$198+Drivers!$D$188*Drivers!D$205-(Drivers!$D$185+Drivers!$D$187*Drivers!$D$186))/Drivers!$D$181
A10: 1300 | B10: =($A10*B$5+Drivers!$E$264*Drivers!D$198+Drivers!$D$188*Drivers!D$205-(Drivers!$D$185+Drivers!$D$187*Drivers!$D$186))/Drivers!$D$181 | C10: =($A10*C$5+Drivers!$E$264*Drivers!D$198+Drivers!$D$188*Drivers!D$205-(Drivers!$D$185+Drivers!$D$187*Drivers!$D$186))/Drivers!$D$181 | D10: =($A10*D$5+Drivers!$E$264*Drivers!D$198+Drivers!$D$188*Drivers!D$205-(Drivers!$D$185+Drivers!$D$187*Drivers!$D$186))/Drivers!$D$181 | E10: =($A10*E$5+Drivers!$E$264*Drivers!D$198+Drivers!$D$188*Drivers!D$205-(Drivers!$D$185+Drivers!$D$187*Drivers!$D$186))/Drivers!$D$181 | F10: =($A10*F$5+Drivers!$E$264*Drivers!D$198+Drivers!$D$188*Drivers!D$205-(Drivers!$D$185+Drivers!$D$187*Drivers!$D$186))/Drivers!$D$181 | G10: =($A10*G$5+Drivers!$E$264*Drivers!D$198+Drivers!$D$188*Drivers!D$205-(Drivers!$D$185+Drivers!$D$187*Drivers!$D$186))/Drivers!$D$181
A11: 1400 | B11: =($A11*B$5+Drivers!$E$264*Drivers!D$198+Drivers!$D$188*Drivers!D$205-(Drivers!$D$185+Drivers!$D$187*Drivers!$D$186))/Drivers!$D$181 | C11: =($A11*C$5+Drivers!$E$264*Drivers!D$198+Drivers!$D$188*Drivers!D$205-(Drivers!$D$185+Drivers!$D$187*Drivers!$D$186))/Drivers!$D$181 | D11: =($A11*D$5+Drivers!$E$264*Drivers!D$198+Drivers!$D$188*Drivers!D$205-(Drivers!$D$185+Drivers!$D$187*Drivers!$D$186))/Drivers!$D$181 | E11: =($A11*E$5+Drivers!$E$264*Drivers!D$198+Drivers!$D$188*Drivers!D$205-(Drivers!$D$185+Drivers!$D$187*Drivers!$D$186))/Drivers!$D$181 | F11: =($A11*F$5+Drivers!$E$264*Drivers!D$198+Drivers!$D$188*Drivers!D$205-(Drivers!$D$185+Drivers!$D$187*Drivers!$D$186))/Drivers!$D$181 | G11: =($A11*G$5+Drivers!$E$264*Drivers!D$198+Drivers!$D$188*Drivers!D$205-(Drivers!$D$185+Drivers!$D$187*Drivers!$D$186))/Drivers!$D$181
A12: 1430 | B12: =($A12*B$5+Drivers!$E$264*Drivers!D$198+Drivers!$D$188*Drivers!D$205-(Drivers!$D$185+Drivers!$D$187*Drivers!$D$186))/Drivers!$D$181 | C12: =($A12*C$5+Drivers!$E$264*Drivers!D$198+Drivers!$D$188*Drivers!D$205-(Drivers!$D$185+Drivers!$D$187*Drivers!$D$186))/Drivers!$D$181 | D12: =($A12*D$5+Drivers!$E$264*Drivers!D$198+Drivers!$D$188*Drivers!D$205-(Drivers!$D$185+Drivers!$D$187*Drivers!$D$186))/Drivers!$D$181 | E12: =($A12*E$5+Drivers!$E$264*Drivers!D$198+Drivers!$D$188*Drivers!D$205-(Drivers!$D$185+Drivers!$D$187*Drivers!$D$186))/Drivers!$D$181 | F12: =($A12*F$5+Drivers!$E$264*Drivers!D$198+Drivers!$D$188*Drivers!D$205-(Drivers!$D$185+Drivers!$D$187*Drivers!$D$186))/Drivers!$D$181 | G12: =($A12*G$5+Drivers!$E$264*Drivers!D$198+Drivers!$D$188*Drivers!D$205-(Drivers!$D$185+Drivers!$D$187*Drivers!$D$186))/Drivers!$D$181
